
<mujoco model="task_3">
    <option gravity="0 -9.81 0" integrator="Euler"/>
    <statistic center="0.07200000000000001 0 0" extent="0.25"/>

    <default>
        <joint axis="0 1 0" damping="0.00005"/>
        <geom type="capsule" size="0.002"/>
    </default>

    <asset>
        <texture name="texplane" type="2d" builtin="checker"
                 rgb1="0.85 0.85 0.85" rgb2="0.85 0.85 0.85"
                 width="512" height="512" mark="none"/>
        <material name="matplane" reflectance="0"
                  texture="texplane" texrepeat="1 1"
                  texuniform="true"/>
    </asset>

    <worldbody>

        <light pos="0 0 0.3"/>
        <light pos="0 0 3" dir="0 0 -1" directional="false"/>

        <geom name="floor" type="plane" pos="0 0 -0.14"
              size="0 0 1"
              material="matplane" conaffinity="15" condim="3"/>

        <body pos="0 0 0">
            <geom name="left_support" type="box"
                  size="0.002 0.03 0.03"
                  rgba="0.0314 0.6353 0.0 0.65"/>

            <geom fromto="0 0 0 0.079 0 0"
                  rgba="0.7 0.7 0.7 1"
                  contype="0" conaffinity="0"/>

            <site name="s1" pos="0.002 0 0.049"  size="0.002" rgba="1 1 1 1"/>
            <site name="s2" pos="0.002 0 -0.049" size="0.002" rgba="1 1 1 1"/>

            <body pos="0.079 0 0">
                <joint name="axis1"/>

                <geom fromto="0 0 0 0.032 0 0"
                      rgba="0.7 0.7 0.7 1"/>

                <body name="pulley1" pos="0 0 0">
                    <joint name="p1_hinge" type="hinge"
                           axis="0 1 0" stiffness="5" damping="0.005"/>

                    <geom name="Pulley1" type="cylinder"
                          fromto="0 0.005 0 0 -0.005 0"
                          size="0.049"
                          rgba="1.0 0.6588 0.0 0.65"/>

                    <site name="s3" pos="0 0 0.049"  size="0.002" rgba="1 1 1 1"/>
                    <site name="s4" pos="0 0 -0.049" size="0.002" rgba="1 1 1 1"/>
                </body>

                <body pos="0.032 0 0">
                    <joint name="axis2"/>

                    <geom fromto="0 0 0 0.033 0 0"
                          rgba="0.7 0.7 0.7 1"/>

                    <body name="pulley2" pos="0 0 0">
                        <joint name="p2_hinge" type="hinge"
                               axis="0 1 0" stiffness="5" damping="0.005"/>

                        <geom name="Pulley2" type="cylinder"
                              fromto="0 0.005 0 0 -0.005 0"
                              size="0.016"
                              rgba="1.0 0.6588 0.0 0.65"/>

                        <site name="s5" pos="0 0 0.016"  size="0.002" rgba="1 1 1 1"/>
                        <site name="s6" pos="0 0 -0.016" size="0.002" rgba="1 1 1 1"/>

                        <site name="s7" pos="0.033 0 0.016"  size="0.002" rgba="1 1 1 1"/>
                        <site name="s8" pos="0.033 0 -0.016" size="0.002" rgba="1 1 1 1"/>
                    </body>

                    <body>
                        <geom name="right_support" type="box"
                              size="0.002 0.03 0.03"
                              rgba="0.0314 0.6353 0.0 0.65"
                              pos="0.033 0 0"/>
                    </body>
                </body>
            </body>
        </body>
    </worldbody>

    <tendon>
        <!-- тяга 1: (0, 15, 162, 0.65) -->
        <spatial stiffness="5" width="0.0015"
                 rgba="0.0 0.0588 0.6353 0.65">
            <site site="s1"/>
            <geom geom="Pulley1" sidesite="s3"/>
            <site site="s3"/>
            <geom geom="Pulley2" sidesite="s6"/>
            <site site="s8"/>
        </spatial>

        <spatial stiffness="5" width="0.0015"
                 rgba="0.7843 0.0 0.0 0.65">
            <site site="s2"/>
            <geom geom="Pulley1" sidesite="s4"/>
            <site site="s4"/>
            <geom geom="Pulley2" sidesite="s5"/>
            <site site="s7"/>
        </spatial>
    </tendon>
</mujoco>
